// Test script to verify improved error handling in seed.js
const mysql = require('mysql2/promise');

// Mock error objects to test the error handling logic
function testErrorHandling() {
  console.log('🧪 Testing improved error handling logic...\n');

  // Test cases
  const testCases = [
    {
      name: 'MySQL Duplicate Entry Error (code)',
      error: { code: 'ER_DUP_ENTRY', errno: 1062, message: 'Duplicate entry for key PRIMARY' },
      shouldThrow: false
    },
    {
      name: 'MySQL Duplicate Entry Error (errno only)',
      error: { errno: 1062, message: 'Duplicate entry for key PRIMARY' },
      shouldThrow: false
    },
    {
      name: 'Other MySQL Error',
      error: { code: 'ER_NO_SUCH_TABLE', errno: 1146, message: 'Table does not exist' },
      shouldThrow: true
    },
    {
      name: 'Generic Error',
      error: { message: 'Some generic error' },
      shouldThrow: true
    },
    {
      name: 'Error with duplicate in message but different code',
      error: { code: 'ER_OTHER', errno: 9999, message: 'Duplicate entry somewhere in message' },
      shouldThrow: true
    }
  ];

  let passedTests = 0;
  
  testCases.forEach((testCase, index) => {
    try {
      console.log(`Test ${index + 1}: ${testCase.name}`);
      
      // Simulate the error handling logic from seed.js
      const error = testCase.error;
      let shouldRethrow = (error.code !== 'ER_DUP_ENTRY' && error.errno !== 1062);
      
      if (shouldRethrow && !testCase.shouldThrow) {
        console.log('❌ FAILED: Should not have rethrown error');
        return;
      }
      
      if (!shouldRethrow && testCase.shouldThrow) {
        console.log('❌ FAILED: Should have rethrown error');
        return;
      }
      
      console.log('✅ PASSED');
      passedTests++;
      
    } catch (error) {
      console.log('❌ FAILED: Unexpected error', error.message);
    }
  });
  
  console.log(`\n📊 Results: ${passedTests}/${testCases.length} tests passed`);
  
  if (passedTests === testCases.length) {
    console.log('🎉 All tests passed! Error handling logic is robust.');
  } else {
    console.log('❌ Some tests failed. Review the error handling logic.');
  }
}

testErrorHandling();
